Workbook

Sheet Input
A1: INPUT DATA – Configuration and Parameters
A2: Fill in blue fields. Guidance for solution choices, not definitive.
A3: QUESTIONS | B3: ANSWERS | C3: GUIDANCE
A4: 1. LOCAL CONDITIONS – Communication
A5: 4G coverage at location? | B5: No | C5: Check Telenor coverage map
A6: NB-IoT coverage at location? | B6: No | C6: Check Telenor coverage map
A7: Line of sight < 15 km to base station? | B7: No | C7: Use a line-of-sight calculator, NKOM.no has a free web solution.
A8: Two-way control required (remote-controlled valve)? | B8: No | C8: Two-way = requires 4G or satellite
A9: 2. FACILITY TYPE & RELEASE METHOD (NVE Ch. 3–5) | C9: Concession terms determine release method and measurement technique
A10: Release method (arrangement)? | B10: Pipe via intake | C10: NVE Guide 3/2020 Ch. 3–5. Incl. Coanda screens (Ch. 5.4)
A11: Fish passage at intake? | B11: Yes | C11: NVE Ch. 5: Extra attraction water + up-/downstream migration
A12: Required minimum flow (l/s)? | B12: 20 | C12: Specified in the concession (m³/s or l/s)
A13: Low conductivity in water? | B13: No | C13: Pipe only: Yes = ultrasound, No = electromagnetic
A14: Ice problems at measurement site? | B14: No | C14: NVE: Ice/sediment affects measurement profile and sensor selection
A15: Difficult access to intake? | B15: No | C15: NVE Ch. 9: Affects logger backup and camera requirements
A16: Linear flow at intended measurement site? | B16: No | C16: Pipe only: Air affects Doppler/ultrasound. Requires straight run.
A17: Sediment or surge problem? | B17: No | C17: Yes = bubble tube recommended over pressure cell
A18: 3. OPERATIONS – Inspections & Autonomy | C18: Determines logger redundancy and secondary source
A19: Number of inspections/visits per year? | B19: 4 | C19: NVE: min. annual main inspection. ≤4 = 2 loggers. Must be a value between 3–30 days
A20: Battery bank size (Ah) | B20: 500 | C20: =IF(A20="Desired autonomy (days)","Typically 3–14 days","Typically 100–500 Ah") -> Typically 100–500 Ah
A21: Desired zero-emission (methanol)? | B21: No | C21: Yes = fuel cell, No = visit frequency determines diesel/methanol
A27: TECHNICAL PARAMETERS
A29: Solar Panel System
A30: Parameter | B30: Unit | C30: Value | D30: Comment
A31: PV panel power | B31: Wp | C31: 425 | D31: From the datasheet for selected panel
A32: Number of panels | B32: pcs | C32: 2 | D32: The configurator calculates this
A33: System efficiency | B33: % | C33: 0.8 | D33: Total system loss incl. cables, inverter, temperature. Typically 75–85%.
A34: Expected lifespan in years | B34: yr | C34: 25 | D34: Expected lifespan for PV panels
A36: Battery Bank
A37: Parameter | B37: Unit | C37: Value | D37: Comment
A38: Nominal voltage | B38: V | C38: 12.8 | D38: System nominal voltage (12V or 24V)
A39: Max depth of discharge (DoD) | B39: factor (0–1) | C39: 0.8 | D39: LiFePO4: 80–90%, Lead-acid: 50%
A40: Cycle lifespan | B40: cycles | C40: 6000 | D40: LiFePO4: ~3000–6000, AGM: ~500–1200
A42: Fuel Cell
A43: Parameter | B43: Unit | C43: Value | D43: Comment
A44: Purchase cost | B44: kr | C44: 88000 | D44: Purchase price excl./incl. VAT per supplier
A45: Power | B45: W | C45: 82 | D45: Nominal power from datasheet (W)
A46: Fuel consumption | B46: l/kWh | C46: 0.9 | D46: Methanol fuel consumption per kWh produced
A47: Fuel price (methanol) | B47: kr/l | C47: 75 | D47: Market price methanol per liter
A48: Lifespan | B48: hours | C48: 6500 | D48: Expected lifespan in operating hours
...

Sheet Power Budget
A1: Power Budget – Equipment List
A2: ON/OFF | B2: Unit | C2: Power (W) | D2: Current Draw (A) | E2: Consumption (Wh/day) | F2: Current Draw (Ah/day) | G2: Consumption (Wh/week) | H2: Current Draw (Ah/week)
A3: TRUE | B3: Victron BMS | C3: 0.1 | D3: =C3/Input!$C$38 -> 0.0078125 | E3: =C3*24*(A3) -> 2.4 | F3: =D3*24*(A3) -> 0.1875 | G3: =E3*7 -> 16.8 | H3: =F3*7 -> 1.3125
A4: TRUE | B4: VICTRON Lynx Distributor | C4: 2.4 | D4: =C4/Input!$C$38 -> 0.1875 | E4: =C4*24*(A4) -> 57.6 | F4: =D4*24*(A4) -> 4.5 | G4: =E4*7 -> 403.2 | H4: =F4*7 -> 31.5
A5: TRUE | B5: VICTRON Orion TR Omformer DC-DC 12>24V 10A | C5: 1.2 | D5: =C5/Input!$C$38 -> 0.09375 | E5: =C5*24*(A5) -> 28.8 | F5: =D5*24*(A5) -> 2.25 | G5: =E5*7 -> 201.6 | H5: =F5*7 -> 15.75
A6: TRUE | B6: Victron Cerbo GX - MK2 | C6: 2.8 | D6: =C6/Input!$C$38 -> 0.21875 | E6: =C6*24*(A6) -> 67.2 | F6: =D6*24*(A6) -> 5.25 | G6: =E6*7 -> 470.4 | H6: =F6*7 -> 36.75
A7: TRUE | B7: VICTRON SmartSolar MPPT 250/100-TR VE.Can | C7: 0.042 | D7: =C7/Input!$C$38 -> 0.00328125 | E7: =C7*24*(A7) -> 1.008 | F7: =D7*24*(A7) -> 0.07875 | G7: =E7*7 -> 7.056 | H7: =F7*7 -> 0.55125
A8: TRUE | B8: Siemens FMS5020 | C8: 6.45 | D8: =C8/Input!$C$38 -> 0.50390625 | E8: =C8*24*(A8) -> 154.8 | F8: =D8*24*(A8) -> 12.09375 | G8: =E8*7 -> 1083.6 | H8: =F8*7 -> 84.65625
A9: TRUE | B9: Teltonika RUT956 | C9: 7 | D9: =C9/Input!$C$38 -> 0.546875 | E9: =C9*24*(A9) -> 168 | F9: =D9*24*(A9) -> 13.125 | G9: =E9*7 -> 1176 | H9: =F9*7 -> 91.875
A10: TRUE | B10: Efoy Pro 1800 | C10: 0.5 | D10: =C10/Input!$C$38 -> 0.0390625 | E10: =C10*24*(A10) -> 12 | F10: =D10*24*(A10) -> 0.9375 | G10: =E10*7 -> 84 | H10: =F10*7 -> 6.5625
A11: TRUE | B11: Efoy Fuel Manager FM4 | C11: 0.0374 | D11: =C11/Input!$C$38 -> 0.002921875 | E11: =C11*24*(A11) -> 0.8976 | F11: =D11*24*(A11) -> 0.070125 | G11: =E11*7 -> 6.2832 | H11: =F11*7 -> 0.490875
A12: TRUE | B12: Datalogger | C12: 7 | D12: =C12/Input!$C$38 -> 0.546875 | E12: =C12*24*(A12) -> 168 | F12: =D12*24*(A12) -> 13.125 | G12: =E12*7 -> 1176 | H12: =F12*7 -> 91.875
A13: TRUE | D13: =C13/Input!$C$38 -> 0 | E13: =C13*24*(A13) -> 0 | F13: =D13*24*(A13) -> 0 | G13: =E13*7 -> 0 | H13: =F13*7 -> 0
A14: TRUE | D14: =C14/Input!$C$38 -> 0 | E14: =C14*24*(A14) -> 0 | F14: =D14*24*(A14) -> 0 | G14: =E14*7 -> 0 | H14: =F14*7 -> 0
A15: TRUE | D15: =C15/Input!$C$38 -> 0 | E15: =C15*24*(A15) -> 0 | F15: =D15*24*(A15) -> 0 | G15: =E15*7 -> 0 | H15: =F15*7 -> 0
A16: TRUE | D16: =C16/Input!$C$38 -> 0 | E16: =C16*24*(A16) -> 0 | F16: =D16*24*(A16) -> 0 | G16: =E16*7 -> 0 | H16: =F16*7 -> 0
A17: TRUE | D17: =C17/Input!$C$38 -> 0 | E17: =C17*24*(A17) -> 0 | F17: =D17*24*(A17) -> 0 | G17: =E17*7 -> 0 | H17: =F17*7 -> 0
A18: TRUE | D18: =C18/Input!$C$38 -> 0 | E18: =C18*24*(A18) -> 0 | F18: =D18*24*(A18) -> 0 | G18: =E18*7 -> 0 | H18: =F18*7 -> 0
A19: Total | C19: =SUM(C3:C18) -> 27.5294 | D19: =SUM(D3:D18) -> 2.1507344 | E19: =SUM(E3:E18) -> 660.7056 | F19: =SUM(F3:F18) -> 51.617625 | G19: =SUM(G3:G18) -> 4624.9392 | H19: =SUM(H3:H18) -> 361.32337

Sheet Results
A1: RECOMMENDATION – Results and Energy Balance
A2: Updated automatically from Input Data and Power Budget. Guidance – not definitive.
A3: Recommended Configuration
A4: Parameter | B4: Unit | C4: Comment
A5: Measurement Method | B5: =_xlfn.LET(_xlpm.slip,Input!B10,_xlpm.fish,Input!B11,_xlpm.lowcond,Input!B13,_xlpm.ice,Input!B14,_xlpm.linflow,Input!B16,_xlpm.sensor,IF(_xlpm.ice="Yes","Bubble tube or pressure cell","Pressure cell, bubble tube, float or ultrasound/radar sensor"),_xlpm.flowmeter,IF(_xlpm.linflow="Yes",IF(_xlpm.lowcond="Yes","Orifice plate or ultrasound transit time","Electromagnetic, orifice plate or ultrasound transit time"),IF(_xlpm.lowcond="Yes","Orifice plate or ADP","Electromagnetic, orifice plate or ADP")),IF(_xlpm.slip="Pipe via intake",_xlpm.flowmeter&" flow meter"&IF(_xlpm.fish="Yes",". "&_xlpm.sensor,""),IF(_xlpm.slip="Pipe through dam",_xlpm.sensor&". Measurement profile downstream of dam",IF(_xlpm.slip="Gate/bottom valve",_xlpm.sensor&" and gate opening. Measurement profile downstream of release point",IF(_xlpm.slip="Notch in dam (V-profile)",_xlpm.sensor&". Measurement profile downstream of release point","Select arrangement"))))) -> Electromagnetic, orifice plate or ADP flow meter. Pressure cell, bubble tube, float or ultrasound/radar sensor | C5: Select flow meter per recommended method
A6: Communication | B6: =IF(Input!B5="Yes","4G router",IF(Input!B6="Yes","NB-IoT",IF(Input!B7="Yes","LoRaWAN","Satellite modem"))) -> Satellite modem | C6: Select modem/gateway based on coverage
A7: Logger | B7: =IF(OR(Input!B15="Yes",Input!B19<=4),"2 loggers + backup logger","1 logger") -> 2 loggers + backup logger | C7: See NVE requirements for specification
A8: Energy Monitoring | B8: =IF(Input!B5="Yes","Yes","No") -> No | C8: Optional – requires 4G
A9: Secondary Source | B9: =IF(Input!B21="Yes","Fuel cell (methanol)",IF(Input!B19<=3,"Fuel cell (methanol)","Diesel generator")) -> Diesel generator | C9: Contact supplier
A10: Secondary Source Power | B10: =IF(Results!$B$9="Diesel generator", Input!$C$53, Input!$C$45) -> 6500 | C10: Contact supplier
A11: Solar Panel (number of panels) | B11: =Input!C32 -> 2 | C11: Select panel based on available area
A12: Battery (Ah) | B12: =IF(Input!A20="Battery bank size (Ah)",Input!B20,ROUND(('Power Budget'!E19*Input!B20)/(Input!C38*Input!C39),0)) -> 500 | C12: =IF(Input!A20="Desired autonomy (days)","Sized from autonomy requirement","Manually specified battery bank") -> Manually specified battery bank
A13: Fuel Consumption (l/yr) | B13: =ROUND(SUM(F27:F38),1) -> 51.3 | C13: Calculated from energy balance
A14: Ice Adaptation | B14: =IF(Input!B14="Yes",IF(Input!B10="Pipe via intake","Frost-protected sensor housing / heat cable","Ice reduction measurement profile"),"Standard") -> Standard
A15: Operational Requirements | B15: =IF(Input!B10="Pipe via intake","Straight run + laminar flow"&IF(Input!B15="Yes"," + camera",""),"See NVE guidelines") -> Straight run + laminar flow
A16: NVE REQUIREMENTS (Guidelines for Hydrological Investigations)
A17: Parameter | B17: Value | C17: Source
A18: Measurement Frequency | B18: Min. 1 time/hour | C18: NVE requirement, determined by concession.
A19: Accuracy | B19: ±5 % | C19: NVE requirement
A20: Data Availability | B20: Min. 97 % of the year | C20: NVE requirement
A21: Data Loggers and Water Level Sensor | B21: 2 pcs (each) | C21: NVE recommendation
A22: Control Measurement | B22: Every 3rd year | C22: NVE requirement – calibration
A23: Source: NVE Guide 3/2020 + Guidelines for Hydrological Investigations
A25: ="Energy Balance – Annual Overview ("&B9&")" -> Energy Balance – Annual Overview (Diesel generator)
A26: Month | B26: Days | C26: Solar Panel Production (kWh) | D26: Energy Balance (kWh) | E26: Operating Time (h) | F26: Fuel (l) | G26: Fuel Cost (kr)
A27: Jan | B27: 31 | C27: =Input!C66*(Input!$C$31*Input!$C$32/1000)*Input!$C$33 -> 0.075238806 | D27: =C27-('Power Budget'!$E$19*B27)/1000 -> -20.406635 | E27: =IF(D27<0, ABS(D27)/(IF($B$9="Diesel generator",Input!$C$53,Input!$C$45)/1000), 0) -> 3.1394823 | F27: =IF(D27<0, ABS(D27)*IF($B$9="Diesel generator",Input!$C$54,Input!$C$46), 0) -> 10.203317 | G27: =F27*IF(Results!$B$9="Diesel generator", Input!$C$55, Input!$C$47) -> 184.68004
A28: Feb | B28: 28 | C28: =Input!C67*(Input!$C$31*Input!$C$32/1000)*Input!$C$33 -> 0.69415426 | D28: =C28-('Power Budget'!$E$19*B28)/1000 -> -17.805603 | E28: =IF(D28<0, ABS(D28)/(IF($B$9="Diesel generator",Input!$C$53,Input!$C$45)/1000), 0) -> 2.7393235 | F28: =IF(D28<0, ABS(D28)*IF($B$9="Diesel generator",Input!$C$54,Input!$C$46), 0) -> 8.9028013 | G28: =F28*IF(Results!$B$9="Diesel generator", Input!$C$55, Input!$C$47) -> 161.1407
A29: Mar | B29: 31 | C29: =Input!C68*(Input!$C$31*Input!$C$32/1000)*Input!$C$33 -> 14.581835 | D29: =C29-('Power Budget'!$E$19*B29)/1000 -> -5.9000387 | E29: =IF(D29<0, ABS(D29)/(IF($B$9="Diesel generator",Input!$C$53,Input!$C$45)/1000), 0) -> 0.90769826 | F29: =IF(D29<0, ABS(D29)*IF($B$9="Diesel generator",Input!$C$54,Input!$C$46), 0) -> 2.9500193 | G29: =F29*IF(Results!$B$9="Diesel generator", Input!$C$55, Input!$C$47) -> 53.39535
A30: Apr | B30: 30 | C30: =Input!C69*(Input!$C$31*Input!$C$32/1000)*Input!$C$33 -> 41.77832 | D30: =C30-('Power Budget'!$E$19*B30)/1000 -> 21.957152 | E30: =IF(D30<0, ABS(D30)/(IF($B$9="Diesel generator",Input!$C$53,Input!$C$45)/1000), 0) -> 0 | F30: =IF(D30<0, ABS(D30)*IF($B$9="Diesel generator",Input!$C$54,Input!$C$46), 0) -> 0 | G30: =F30*IF(Results!$B$9="Diesel generator", Input!$C$55, Input!$C$47) -> 0
A31: May | B31: 31 | C31: =Input!C70*(Input!$C$31*Input!$C$32/1000)*Input!$C$33 -> 53.960659 | D31: =C31-('Power Budget'!$E$19*B31)/1000 -> 33.478785 | E31: =IF(D31<0, ABS(D31)/(IF($B$9="Diesel generator",Input!$C$53,Input!$C$45)/1000), 0) -> 0 | F31: =IF(D31<0, ABS(D31)*IF($B$9="Diesel generator",Input!$C$54,Input!$C$46), 0) -> 0 | G31: =F31*IF(Results!$B$9="Diesel generator", Input!$C$55, Input!$C$47) -> 0
A32: Jun | B32: 30 | C32: =Input!C71*(Input!$C$31*Input!$C$32/1000)*Input!$C$33 -> 53.925582 | D32: =C32-('Power Budget'!$E$19*B32)/1000 -> 34.104414 | E32: =IF(D32<0, ABS(D32)/(IF($B$9="Diesel generator",Input!$C$53,Input!$C$45)/1000), 0) -> 0 | F32: =IF(D32<0, ABS(D32)*IF($B$9="Diesel generator",Input!$C$54,Input!$C$46), 0) -> 0 | G32: =F32*IF(Results!$B$9="Diesel generator", Input!$C$55, Input!$C$47) -> 0
A33: Jul | B33: 31 | C33: =Input!C72*(Input!$C$31*Input!$C$32/1000)*Input!$C$33 -> 54.83075 | D33: =C33-('Power Budget'!$E$19*B33)/1000 -> 34.348876 | E33: =IF(D33<0, ABS(D33)/(IF($B$9="Diesel generator",Input!$C$53,Input!$C$45)/1000), 0) -> 0 | F33: =IF(D33<0, ABS(D33)*IF($B$9="Diesel generator",Input!$C$54,Input!$C$46), 0) -> 0 | G33: =F33*IF(Results!$B$9="Diesel generator", Input!$C$55, Input!$C$47) -> 0
A34: Aug | B34: 31 | C34: =Input!C73*(Input!$C$31*Input!$C$32/1000)*Input!$C$33 -> 48.564171 | D34: =C34-('Power Budget'!$E$19*B34)/1000 -> 28.082297 | E34: =IF(D34<0, ABS(D34)/(IF($B$9="Diesel generator",Input!$C$53,Input!$C$45)/1000), 0) -> 0 | F34: =IF(D34<0, ABS(D34)*IF($B$9="Diesel generator",Input!$C$54,Input!$C$46), 0) -> 0 | G34: =F34*IF(Results!$B$9="Diesel generator", Input!$C$55, Input!$C$47) -> 0
A35: Sep | B35: 30 | C35: =Input!C74*(Input!$C$31*Input!$C$32/1000)*Input!$C$33 -> 25.645589 | D35: =C35-('Power Budget'!$E$19*B35)/1000 -> 5.8244213 | E35: =IF(D35<0, ABS(D35)/(IF($B$9="Diesel generator",Input!$C$53,Input!$C$45)/1000), 0) -> 0 | F35: =IF(D35<0, ABS(D35)*IF($B$9="Diesel generator",Input!$C$54,Input!$C$46), 0) -> 0 | G35: =F35*IF(Results!$B$9="Diesel generator", Input!$C$55, Input!$C$47) -> 0
A36: Oct | B36: 31 | C36: =Input!C75*(Input!$C$31*Input!$C$32/1000)*Input!$C$33 -> 2.0774385 | D36: =C36-('Power Budget'!$E$19*B36)/1000 -> -18.404435 | E36: =IF(D36<0, ABS(D36)/(IF($B$9="Diesel generator",Input!$C$53,Input!$C$45)/1000), 0) -> 2.8314516 | F36: =IF(D36<0, ABS(D36)*IF($B$9="Diesel generator",Input!$C$54,Input!$C$46), 0) -> 9.2022175 | G36: =F36*IF(Results!$B$9="Diesel generator", Input!$C$55, Input!$C$47) -> 166.56014
A37: Nov | B37: 30 | C37: =Input!C76*(Input!$C$31*Input!$C$32/1000)*Input!$C$33 -> 0.17662161 | D37: =C37-('Power Budget'!$E$19*B37)/1000 -> -19.644546 | E37: =IF(D37<0, ABS(D37)/(IF($B$9="Diesel generator",Input!$C$53,Input!$C$45)/1000), 0) -> 3.0222379 | F37: =IF(D37<0, ABS(D37)*IF($B$9="Diesel generator",Input!$C$54,Input!$C$46), 0) -> 9.8222732 | G37: =F37*IF(Results!$B$9="Diesel generator", Input!$C$55, Input!$C$47) -> 177.78314
A38: Dec | B38: 31 | C38: =Input!C77*(Input!$C$31*Input!$C$32/1000)*Input!$C$33 -> 0.011566629 | D38: =C38-('Power Budget'!$E$19*B38)/1000 -> -20.470307 | E38: =IF(D38<0, ABS(D38)/(IF($B$9="Diesel generator",Input!$C$53,Input!$C$45)/1000), 0) -> 3.149278 | F38: =IF(D38<0, ABS(D38)*IF($B$9="Diesel generator",Input!$C$54,Input!$C$46), 0) -> 10.235153 | G38: =F38*IF(Results!$B$9="Diesel generator", Input!$C$55, Input!$C$47) -> 185.25628
A39: SUM | C39: =SUM(C27:C38) -> 296.32193 | D39: =SUM(D27:D38) -> 55.164383 | E39: =SUM(E27:E38) -> 15.789471 | F39: =SUM(F27:F38) -> 51.315782 | G39: =SUM(G27:G38) -> 928.81566
A41: Economics – Total Cost of Ownership (TCO)
A42: Parameter | B42: Unit | C42: Fuel Cell (methanol) | D42: Diesel Generator | E42: Comment
...
